data/sample_orders.csv
order_id,symbol,side,order_type,price,quantity,timestamp
1,AAPL,sell,limit,10100,100,1
2,AAPL,sell,limit,10150,200,2
3,AAPL,sell,limit,10100,50,3
4,AAPL,buy,limit,10000,150,4
5,AAPL,buy,limit,10050,100,5
3,AAPL,cancel,cancel,0,0,6
7,AAPL,buy,limit,10100,120,7
8,AAPL,buy,market,0,50,8
9,AAPL,sell,market,0,400,9
10,AAPL,sell,limit,10100,30,10
11,AAPL,buy,limit,-5,10,11
12,AAPL,buy,limit,10100,30,12
